<robot name="robot_arm">
 	<link name="base_link">
		<visual>
            <origin xyz = "0.0 0.0 -0.025" rpy="0 0 0"/>
            <geometry>
                <box size="0.05 0.05 0.05"/>
            </geometry>
        </visual>	
	</link>

    <link name="arm_1">
		<visual>
          <origin xyz="0.032 0.120 0.077" rpy="-1 0 -0.264" />
            <geometry>
                <cylinder length="0.292" radius="0.01"/>
            </geometry>
        </visual> 	
	</link>


    <joint name="motor1" type="revolute">
      <parent link="base_link"/>
      <child link="arm_1"/>
      <origin xyz="0 0 0" rpy="0 0 -2.6" />
      <axis xyz="0 0 1"/>
      <limit lower="-0.01" upper="3.14" />
    </joint>


    
    <link name="arm_2">
		<visual>
          <origin xyz="0.01 0.00035 0.225" rpy="-0.015 0 -1.23" />
            <geometry>
                <cylinder length="0.450" radius="0.01"/>
            </geometry>
        </visual> 	
	</link>
    <joint name="motor2" type="revolute">
      <parent link="arm_1"/>
      <child link="arm_2"/>
      <origin xyz="0.064 0.240 0.154" rpy="-3.5 0 0" />
      <axis xyz="1 0 0"/>
      <limit lower="-0.01" upper="4.71" />
    </joint>
    



    <link name="arm_3">
		<visual>
          <origin xyz="0.007 0.029 0.009" rpy="-1.329 0 -0.36" />
            <geometry>
                <cylinder length="0.0633" radius="0.01"/>
            </geometry>
        </visual>   
	</link>
 <joint name="motor3" type="revolute">
      <parent link="arm_2"/>
      <child link="arm_3"/>
      <origin xyz="0.02 0.007 0.450" rpy="0 0 -4.8" />
      <axis xyz="0 0 1"/>
        <limit lower="-0.01" upper="4.71" />
    </joint>
    

    
    
    <link name="arm_4">
		<visual>
          <origin xyz="0.0325 0.0025 0.1335" rpy="-0.259 0 -1.47" />
            <geometry>
                <cylinder length="0.274" radius="0.01"/>
            </geometry>
        </visual>
    </link>
    <joint name="motor4" type="revolute">
      <parent link="arm_3"/>
      <child link="arm_4"/>
      <origin xyz="0.018 0.058 0.018" rpy="0 3.1 0" />
      <axis xyz="0 1 0"/>
      <limit lower="-0.01" upper="5.23" />       
    </joint>


    
    
    <link name="arm_5">
		<visual>
          <origin xyz="0.0075 0.026 0.006" rpy="-1.5 0 -0.22" />
            <geometry>
                <cylinder length="0.055" radius="0.01"/>
            </geometry>
        </visual> 	
	</link>
    <joint name="motor5" type="revolute">
      <parent link="arm_4"/>
      <child link="arm_5"/>
      <origin xyz="0.065 0.005 0.267" rpy="0 2.5 0" />
      <axis xyz="0 1 0"/>
      <limit lower="-0.01" upper="5.23" />       
    </joint>

    
    
    <link name="camera">
		<visual>
          <origin xyz="0 0 0" rpy="0 1.57 0" />
            <geometry>
                <cylinder length="0.073" radius="0.01"/>
            </geometry>
        </visual> 	
	</link>
    <joint name="motor6" type="revolute">
      <parent link="arm_5"/>
      <child link="camera"/>
      <origin xyz="0.015 0.052 0.012" rpy="0 0 0" />
      <axis xyz="0 0 1"/>
      <limit lower="-0.01" upper="5.23" />
    </joint>
    
</robot>